Workbook

Sheet Historical_Production_Data
A1: Date | B1: Oil (BBL) | C1: Casinghead (MCF) | D1: GW Gas (MCF) | E1: Condensate (BBL) | F1: TIME
A2: 43101 | B2: 977 | C2: 8274 | D2: 54178 | E2: 581 | F2: =1 -> 1
A3: 43132 | B3: 679 | C3: 9237 | D3: 48959 | E3: 445 | F3: =F2+1 -> 2
A4: 43160 | B4: 374 | C4: 7522 | D4: 54378 | E4: 442 | F4: =F3+1 -> 3
A5: 43191 | B5: 442 | C5: 6620 | D5: 51098 | E5: 364 | F5: =F4+1 -> 4
A6: 43221 | B6: 416 | C6: 5651 | D6: 52736 | E6: 415 | F6: =F5+1 -> 5
A7: 43252 | B7: 414 | C7: 6100 | D7: 47572 | E7: 364 | F7: =F6+1 -> 6
A8: 43282 | B8: 392 | C8: 7892 | D8: 53651 | E8: 475 | F8: =F7+1 -> 7
A9: 43313 | B9: 419 | C9: 8134 | D9: 56592 | E9: 518 | F9: =F8+1 -> 8
A10: 43344 | B10: 376 | C10: 6476 | D10: 55583 | E10: 498 | F10: =F9+1 -> 9
A11: 43374 | B11: 836 | C11: 10846 | D11: 56566 | E11: 825 | F11: =F10+1 -> 10
A12: 43405 | B12: 711 | C12: 10832 | D12: 53657 | E12: 590 | F12: =F11+1 -> 11
A13: 43435 | B13: 553 | C13: 7146 | D13: 46971 | E13: 1171 | F13: =F12+1 -> 12
A14: 43466 | B14: 320 | C14: 8479 | D14: 54650 | E14: 741 | F14: =F13+1 -> 13
... A85: 45627 | B85: 265 | C85: 2478 | D85: 13121 | E85: 217 | F85: =F84+1 -> 84
A86: 45658 | F86: =F85+1 -> 85
A87: 45689 | F87: =F86+1 -> 86
A88: 45717 | F88: =F87+1 -> 87
A89: 45748 | F89: =F88+1 -> 88
A90: 45778 | F90: =F89+1 -> 89
A91: 45809 | F91: =F90+1 -> 90
A92: 45839 | F92: =F91+1 -> 91
A93: 45870 | F93: =F92+1 -> 92
A94: 45901 | F94: =F93+1 -> 93
A95: 45931 | F95: =F94+1 -> 94
A96: 45962 | F96: =F95+1 -> 95
A97: 45992 | F97: =F96+1 -> 96
... A445: 56584 | F445: =F444+1 -> 444

Sheet Economic Inputs Parameters
A1: Parameter | B1: Value | C1: Unit | D1: Source/Assumption
A2: Gas Price ($/MCF) | B2: 3 | C2: $/MCF | D2: Market reference (EIA)/Assumed
A3: Oil Price ($/BBL) | B3: 70 | C3: $/BBL | D3: Market reference /Assumed
A4: Monthly OpEx ($) | B4: 3000 | C4: $/month | D4: Assumed Industry Average
A5: Mensal Discount Rate | B5: 0.0083 | C5: $/month | D5: Equivalent to 10% Annual Discount
A6: Capex | B6: =-15000000 -> -15000000 | C6: $ | D6: Initial Investment ( Assumed)

Sheet DCA_Forecast_Model
F1: Parameter | G1: Value | H1: Unit | I1: Cell Reference
F2: qi_Gas | G2: 66087 | H2: MCF/month | I2: $G$2
F3: Di Gas | G3: 0.018 | H3: 1/month | I3: $G$3
F4: Condensate Factor | G4: 77.69 | H4: MCF/BBL | I4: $G$4
A5: TIME | B5: Date | C5: Historical Gas Production (MCF) | D5: Historical Condensate Production (BBL) | E5: Projected Gas Production (MCF) | F5: Projected OIL Production (BBL) | G5: Total Gas Production (MCF) | H5: Total Oil Production (BBL) | I5: EUR GAS (MCF) | J5: EUR OIL (BBL)
A6: =1 -> 1 | B6: Jan 2018 | C6: 54178 | D6: 581 | G6: =IF(A6<=84, C6, E6) -> 54178 | H6: =IF(A6<=84, D6, F6) -> 581 | I6: =SUM(G6:G449) -> 3710711.9 | J6: =SUM(H6:H449) -> 50392.652
A7: =A6+1 -> 2 | B7: Feb 2018 | C7: 48959 | D7: 445 | G7: =IF(A7<=84, C7, E7) -> 48959 | H7: =IF(A7<=84, D7, F7) -> 445
A8: =A7+1 -> 3 | B8: Mar 2018 | C8: 54378 | D8: 442 | G8: =IF(A8<=84, C8, E8) -> 54378 | H8: =IF(A8<=84, D8, F8) -> 442
A9: =A8+1 -> 4 | B9: Apr 2018 | C9: 51098 | D9: 364 | G9: =IF(A9<=84, C9, E9) -> 51098 | H9: =IF(A9<=84, D9, F9) -> 364
A10: =A9+1 -> 5 | B10: May 2018 | C10: 52736 | D10: 415 | G10: =IF(A10<=84, C10, E10) -> 52736 | H10: =IF(A10<=84, D10, F10) -> 415
A11: =A10+1 -> 6 | B11: Jun 2018 | C11: 47572 | D11: 364 | G11: =IF(A11<=84, C11, E11) -> 47572 | H11: =IF(A11<=84, D11, F11) -> 364
A12: =A11+1 -> 7 | B12: Jul 2018 | C12: 53651 | D12: 475 | G12: =IF(A12<=84, C12, E12) -> 53651 | H12: =IF(A12<=84, D12, F12) -> 475
A13: =A12+1 -> 8 | B13: Aug 2018 | C13: 56592 | D13: 518 | G13: =IF(A13<=84, C13, E13) -> 56592 | H13: =IF(A13<=84, D13, F13) -> 518
A14: =A13+1 -> 9 | B14: Sep 2018 | C14: 55583 | D14: 498 | G14: =IF(A14<=84, C14, E14) -> 55583 | H14: =IF(A14<=84, D14, F14) -> 498
A15: =A14+1 -> 10 | B15: Oct 2018 | C15: 56566 | D15: 825 | G15: =IF(A15<=84, C15, E15) -> 56566 | H15: =IF(A15<=84, D15, F15) -> 825
A16: =A15+1 -> 11 | B16: Nov 2018 | C16: 53657 | D16: 590 | G16: =IF(A16<=84, C16, E16) -> 53657 | H16: =IF(A16<=84, D16, F16) -> 590
A17: =A16+1 -> 12 | B17: Dec 2018 | C17: 46971 | D17: 1171 | G17: =IF(A17<=84, C17, E17) -> 46971 | H17: =IF(A17<=84, D17, F17) -> 1171
A18: =A17+1 -> 13 | B18: Jan 2019 | C18: 54650 | D18: 741 | G18: =IF(A18<=84, C18, E18) -> 54650 | H18: =IF(A18<=84, D18, F18) -> 741
... A89: =A88+1 -> 84 | B89: Dec 2024 | C89: 13121 | D89: 217 | G89: =IF(A89<=84, C89, E89) -> 13121 | H89: =IF(A89<=84, D89, F89) -> 217
A90: =A89+1 -> 85 | B90: Jan 2025 | E90: =$G$2*EXP(-$G$3*(A90)) -> 14310.193 | F90: =E90/$G$4 -> 184.19607 | G90: =IF(A90<=84, C90, E90) -> 14310.193 | H90: =IF(A90<=84, D90, F90) -> 184.19607
A91: =A90+1 -> 86 | B91: Feb 2025 | E91: =$G$2*EXP(-$G$3*(A91)) -> 14054.914 | F91: =E91/$G$4 -> 180.9102 | G91: =IF(A91<=84, C91, E91) -> 14054.914 | H91: =IF(A91<=84, D91, F91) -> 180.9102
A92: =A91+1 -> 87 | B92: Mar 2025 | E92: =$G$2*EXP(-$G$3*(A92)) -> 13804.188 | F92: =E92/$G$4 -> 177.68295 | G92: =IF(A92<=84, C92, E92) -> 13804.188 | H92: =IF(A92<=84, D92, F92) -> 177.68295
A93: =A92+1 -> 88 | B93: Apr 2025 | E93: =$G$2*EXP(-$G$3*(A93)) -> 13557.936 | F93: =E93/$G$4 -> 174.51327 | G93: =IF(A93<=84, C93, E93) -> 13557.936 | H93: =IF(A93<=84, D93, F93) -> 174.51327
A94: =A93+1 -> 89 | B94: May 2025 | E94: =$G$2*EXP(-$G$3*(A94)) -> 13316.076 | F94: =E94/$G$4 -> 171.40013 | G94: =IF(A94<=84, C94, E94) -> 13316.076 | H94: =IF(A94<=84, D94, F94) -> 171.40013
A95: =A94+1 -> 90 | B95: Jun 2025 | E95: =$G$2*EXP(-$G$3*(A95)) -> 13078.531 | F95: =E95/$G$4 -> 168.34253 | G95: =IF(A95<=84, C95, E95) -> 13078.531 | H95: =IF(A95<=84, D95, F95) -> 168.34253
A96: =A95+1 -> 91 | B96: Jul 2025 | E96: =$G$2*EXP(-$G$3*(A96)) -> 12845.224 | F96: =E96/$G$4 -> 165.33948 | G96: =IF(A96<=84, C96, E96) -> 12845.224 | H96: =IF(A96<=84, D96, F96) -> 165.33948
A97: =A96+1 -> 92 | B97: Aug 2025 | E97: =$G$2*EXP(-$G$3*(A97)) -> 12616.078 | F97: =E97/$G$4 -> 162.38999 | G97: =IF(A97<=84, C97, E97) -> 12616.078 | H97: =IF(A97<=84, D97, F97) -> 162.38999
A98: =A97+1 -> 93 | B98: Sep 2025 | E98: =$G$2*EXP(-$G$3*(A98)) -> 12391.02 | F98: =E98/$G$4 -> 159.49312 | G98: =IF(A98<=84, C98, E98) -> 12391.02 | H98: =IF(A98<=84, D98, F98) -> 159.49312
A99: =A98+1 -> 94 | B99: Oct 2025 | E99: =$G$2*EXP(-$G$3*(A99)) -> 12169.977 | F99: =E99/$G$4 -> 156.64793 | G99: =IF(A99<=84, C99, E99) -> 12169.977 | H99: =IF(A99<=84, D99, F99) -> 156.64793
A100: =A99+1 -> 95 | B100: Nov 2025 | E100: =$G$2*EXP(-$G$3*(A100)) -> 11952.878 | F100: =E100/$G$4 -> 153.85349 | G100: =IF(A100<=84, C100, E100) -> 11952.878 | H100: =IF(A100<=84, D100, F100) -> 153.85349
A101: =A100+1 -> 96 | B101: Dec 2025 | E101: =$G$2*EXP(-$G$3*(A101)) -> 11739.651 | F101: =E101/$G$4 -> 151.1089 | G101: =IF(A101<=84, C101, E101) -> 11739.651 | H101: =IF(A101<=84, D101, F101) -> 151.1089
... A449: =A448+1 -> 444 | B449: Dec 2054 | E449: =$G$2*EXP(-$G$3*(A449)) -> 22.347788 | F449: =E449/$G$4 -> 0.28765334 | G449: =IF(A449<=84, C449, E449) -> 22.347788 | H449: =IF(A449<=84, D449, F449) -> 0.28765334

Sheet Cash Flow Model
A4: TIME (MONTHS) | B4: Total Gas Production (MCF) | C4: Total Condensate Production (BBL) | D4: Monthly Revenue - Gas ($) | E4: Monthly Revenue - Condensate ($) | F4: Total Monthly Revenue ($) | G4: Monthly Opex ($) | H4: Net Monthly Cash flow (Pre-Capex) ($) | I4: CAPEX ($) | J4: Net Monthly Cash flow (Post-Capex) ($) | K4: Discount Factor | L4: Discounted Monthly Cash Flow ($) | M4: Cumulative Discounted Cash Flow ($)
A5: =1 -> 1 | B5: =DCA_Forecast_Model!G6 -> 54178 | C5: =DCA_Forecast_Model!H6 -> 581 | D5: =B5*'Economic Inputs Parameters'!$B$2 -> 162534 | E5: =C5*'Economic Inputs Parameters'!$B$3 -> 40670 | F5: =D5+E5 -> 203204 | G5: ='Economic Inputs Parameters'!$B$4 -> 3000 | H5: =F5-G5 -> 200204 | I5: ='Economic Inputs Parameters'!$B$6 -> -15000000 | J5: =H5+I5 -> -14799796 | K5: =1/(1+'Economic Inputs Parameters'!$B$5)^(A5) -> 0.99176832 | L5: =J5*K5 -> -14677969 | M5: =L5 -> -14677969
A6: =A5+1 -> 2 | B6: =DCA_Forecast_Model!G7 -> 48959 | C6: =DCA_Forecast_Model!H7 -> 445 | D6: =B6*'Economic Inputs Parameters'!$B$2 -> 146877 | E6: =C6*'Economic Inputs Parameters'!$B$3 -> 31150 | F6: =D6+E6 -> 178027 | G6: ='Economic Inputs Parameters'!$B$4 -> 3000 | H6: =F6-G6 -> 175027 | I6: 0 | J6: =H6+I6 -> 175027 | K6: =1/(1+'Economic Inputs Parameters'!$B$5)^(A6) -> 0.98360441 | L6: =J6*K6 -> 172157.33 | M6: =M5+L6 -> -14505812
A7: =A6+1 -> 3 | B7: =DCA_Forecast_Model!G8 -> 54378 | C7: =DCA_Forecast_Model!H8 -> 442 | D7: =B7*'Economic Inputs Parameters'!$B$2 -> 163134 | E7: =C7*'Economic Inputs Parameters'!$B$3 -> 30940 | F7: =D7+E7 -> 194074 | G7: ='Economic Inputs Parameters'!$B$4 -> 3000 | H7: =F7-G7 -> 191074 | I7: 0 | J7: =H7+I7 -> 191074 | K7: =1/(1+'Economic Inputs Parameters'!$B$5)^(A7) -> 0.97550769 | L7: =J7*K7 -> 186394.16 | M7: =M6+L7 -> -14319417
A8: =A7+1 -> 4 | B8: =DCA_Forecast_Model!G9 -> 51098 | C8: =DCA_Forecast_Model!H9 -> 364 | D8: =B8*'Economic Inputs Parameters'!$B$2 -> 153294 | E8: =C8*'Economic Inputs Parameters'!$B$3 -> 25480 | F8: =D8+E8 -> 178774 | G8: ='Economic Inputs Parameters'!$B$4 -> 3000 | H8: =F8-G8 -> 175774 | I8: 0 | J8: =H8+I8 -> 175774 | K8: =1/(1+'Economic Inputs Parameters'!$B$5)^(A8) -> 0.96747763 | L8: =J8*K8 -> 170057.41 | M8: =M7+L8 -> -14149360
A9: =A8+1 -> 5 | B9: =DCA_Forecast_Model!G10 -> 52736 | C9: =DCA_Forecast_Model!H10 -> 415 | D9: =B9*'Economic Inputs Parameters'!$B$2 -> 158208 | E9: =C9*'Economic Inputs Parameters'!$B$3 -> 29050 | F9: =D9+E9 -> 187258 | G9: ='Economic Inputs Parameters'!$B$4 -> 3000 | H9: =F9-G9 -> 184258 | I9: 0 | J9: =H9+I9 -> 184258 | K9: =1/(1+'Economic Inputs Parameters'!$B$5)^(A9) -> 0.95951366 | L9: =J9*K9 -> 176798.07 | M9: =M8+L9 -> -13972562
A10: =A9+1 -> 6 | B10: =DCA_Forecast_Model!G11 -> 47572 | C10: =DCA_Forecast_Model!H11 -> 364 | D10: =B10*'Economic Inputs Parameters'!$B$2 -> 142716 | E10: =C10*'Economic Inputs Parameters'!$B$3 -> 25480 | F10: =D10+E10 -> 168196 | G10: ='Economic Inputs Parameters'!$B$4 -> 3000 | H10: =F10-G10 -> 165196 | I10: 0 | J10: =H10+I10 -> 165196 | K10: =1/(1+'Economic Inputs Parameters'!$B$5)^(A10) -> 0.95161526 | L10: =J10*K10 -> 157203.03 | M10: =M9+L10 -> -13815359
A11: =A10+1 -> 7 | B11: =DCA_Forecast_Model!G12 -> 53651 | C11: =DCA_Forecast_Model!H12 -> 475 | D11: =B11*'Economic Inputs Parameters'!$B$2 -> 160953 | E11: =C11*'Economic Inputs Parameters'!$B$3 -> 33250 | F11: =D11+E11 -> 194203 | G11: ='Economic Inputs Parameters'!$B$4 -> 3000 | H11: =F11-G11 -> 191203 | I11: 0 | J11: =H11+I11 -> 191203 | K11: =1/(1+'Economic Inputs Parameters'!$B$5)^(A11) -> 0.94378187 | L11: =J11*K11 -> 180453.92 | M11: =M10+L11 -> -13634905
A12: =A11+1 -> 8 | B12: =DCA_Forecast_Model!G13 -> 56592 | C12: =DCA_Forecast_Model!H13 -> 518 | D12: =B12*'Economic Inputs Parameters'!$B$2 -> 169776 | E12: =C12*'Economic Inputs Parameters'!$B$3 -> 36260 | F12: =D12+E12 -> 206036 | G12: ='Economic Inputs Parameters'!$B$4 -> 3000 | H12: =F12-G12 -> 203036 | I12: 0 | J12: =H12+I12 -> 203036 | K12: =1/(1+'Economic Inputs Parameters'!$B$5)^(A12) -> 0.93601296 | L12: =J12*K12 -> 190044.33 | M12: =M11+L12 -> -13444861
A13: =A12+1 -> 9 | B13: =DCA_Forecast_Model!G14 -> 55583 | C13: =DCA_Forecast_Model!H14 -> 498 | D13: =B13*'Economic Inputs Parameters'!$B$2 -> 166749 | E13: =C13*'Economic Inputs Parameters'!$B$3 -> 34860 | F13: =D13+E13 -> 201609 | G13: ='Economic Inputs Parameters'!$B$4 -> 3000 | H13: =F13-G13 -> 198609 | I13: 0 | J13: =H13+I13 -> 198609 | K13: =1/(1+'Economic Inputs Parameters'!$B$5)^(A13) -> 0.928308 | L13: =J13*K13 -> 184370.32 | M13: =M12+L13 -> -13260490
A14: =A13+1 -> 10 | B14: =DCA_Forecast_Model!G15 -> 56566 | C14: =DCA_Forecast_Model!H15 -> 825 | D14: =B14*'Economic Inputs Parameters'!$B$2 -> 169698 | E14: =C14*'Economic Inputs Parameters'!$B$3 -> 57750 | F14: =D14+E14 -> 227448 | G14: ='Economic Inputs Parameters'!$B$4 -> 3000 | H14: =F14-G14 -> 224448 | I14: 0 | J14: =H14+I14 -> 224448 | K14: =1/(1+'Economic Inputs Parameters'!$B$5)^(A14) -> 0.92066647 | L14: =J14*K14 -> 206641.75 | M14: =M13+L14 -> -13053849
A15: =A14+1 -> 11 | B15: =DCA_Forecast_Model!G16 -> 53657 | C15: =DCA_Forecast_Model!H16 -> 590 | D15: =B15*'Economic Inputs Parameters'!$B$2 -> 160971 | E15: =C15*'Economic Inputs Parameters'!$B$3 -> 41300 | F15: =D15+E15 -> 202271 | G15: ='Economic Inputs Parameters'!$B$4 -> 3000 | H15: =F15-G15 -> 199271 | I15: 0 | J15: =H15+I15 -> 199271 | K15: =1/(1+'Economic Inputs Parameters'!$B$5)^(A15) -> 0.91308784 | L15: =J15*K15 -> 181951.93 | M15: =M14+L15 -> -12871897
A16: =A15+1 -> 12 | B16: =DCA_Forecast_Model!G17 -> 46971 | C16: =DCA_Forecast_Model!H17 -> 1171 | D16: =B16*'Economic Inputs Parameters'!$B$2 -> 140913 | E16: =C16*'Economic Inputs Parameters'!$B$3 -> 81970 | F16: =D16+E16 -> 222883 | G16: ='Economic Inputs Parameters'!$B$4 -> 3000 | H16: =F16-G16 -> 219883 | I16: 0 | J16: =H16+I16 -> 219883 | K16: =1/(1+'Economic Inputs Parameters'!$B$5)^(A16) -> 0.9055716 | L16: =J16*K16 -> 199119.8 | M16: =M15+L16 -> -12672777
A17: =A16+1 -> 13 | B17: =DCA_Forecast_Model!G18 -> 54650 | C17: =DCA_Forecast_Model!H18 -> 741 | D17: =B17*'Economic Inputs Parameters'!$B$2 -> 163950 | E17: =C17*'Economic Inputs Parameters'!$B$3 -> 51870 | F17: =D17+E17 -> 215820 | G17: ='Economic Inputs Parameters'!$B$4 -> 3000 | H17: =F17-G17 -> 212820 | I17: 0 | J17: =H17+I17 -> 212820 | K17: =1/(1+'Economic Inputs Parameters'!$B$5)^(A17) -> 0.89811723 | L17: =J17*K17 -> 191137.31 | M17: =M16+L17 -> -12481640
... A448: =A447+1 -> 444 | B448: =DCA_Forecast_Model!G449 -> 22.347788 | C448: =DCA_Forecast_Model!H449 -> 0.28765334 | D448: =B448*'Economic Inputs Parameters'!$B$2 -> 67.043363 | E448: =C448*'Economic Inputs Parameters'!$B$3 -> 20.135734 | F448: =D448+E448 -> 87.179097 | G448: ='Economic Inputs Parameters'!$B$4 -> 3000 | H448: =F448-G448 -> -2912.8209 | I448: 0 | J448: =H448+I448 -> -2912.8209 | K448: =1/(1+'Economic Inputs Parameters'!$B$5)^(A448) -> 0.025476711 | L448: =J448*K448 -> -74.209098 | M448: =M447+L448 -> -5345190.4

Sheet Nodal Analysis Calculations
A1: Parameter | B1: Value | G1: Q (Flow rate)(MCF/month) | H1: P_wf(IPR) Psi | I1: P_wf(VLP) Psi
A2: P_res | B2: 3000 | G2: 0 | H2: =IF($B$2-(G2/$B$4)<0,0,$B$2-(G2/$B$4)) -> 3000 | I2: =$B$3+($B$5*G2) + ($B$6*G2^2) -> 500
A3: P_wh | B3: 500 | G3: 500 | H3: =IF($B$2-(G3/$B$4)<0,0,$B$2-(G3/$B$4)) -> 2950 | I3: =$B$3+($B$5*G3) + ($B$6*G3^2) -> 500.525
A4: J (productivity index) | B4: 10 | G4: =G3+535 -> 1035 | H4: =IF($B$2-(G4/$B$4)<0,0,$B$2-(G4/$B$4)) -> 2896.5 | I4: =$B$3+($B$5*G4) + ($B$6*G4^2) -> 501.14212
A5: A ( VLP Constant) | B5: 0.001 | G5: =G4+535 -> 1570 | H5: =IF($B$2-(G5/$B$4)<0,0,$B$2-(G5/$B$4)) -> 2843 | I5: =$B$3+($B$5*G5) + ($B$6*G5^2) -> 501.81649
A6: B (VLP Constant) | B6: 1e-07 | G6: =G5+535 -> 2105 | H6: =IF($B$2-(G6/$B$4)<0,0,$B$2-(G6/$B$4)) -> 2789.5 | I6: =$B$3+($B$5*G6) + ($B$6*G6^2) -> 502.5481
G7: =G6+535 -> 2640 | H7: =IF($B$2-(G7/$B$4)<0,0,$B$2-(G7/$B$4)) -> 2736 | I7: =$B$3+($B$5*G7) + ($B$6*G7^2) -> 503.33696
A8: P_res | B8: 3000 | G8: =G7+535 -> 3175 | H8: =IF($B$2-(G8/$B$4)<0,0,$B$2-(G8/$B$4)) -> 2682.5 | I8: =$B$3+($B$5*G8) + ($B$6*G8^2) -> 504.18306
A9: P_wh | B9: 500 | G9: =G8+535 -> 3710 | H9: =IF($B$2-(G9/$B$4)<0,0,$B$2-(G9/$B$4)) -> 2629 | I9: =$B$3+($B$5*G9) + ($B$6*G9^2) -> 505.08641
A10: PI | B10: 10 | G10: =G9+535 -> 4245 | H10: =IF($B$2-(G10/$B$4)<0,0,$B$2-(G10/$B$4)) -> 2575.5 | I10: =$B$3+($B$5*G10) + ($B$6*G10^2) -> 506.047
G11: =G10+535 -> 4780 | H11: =IF($B$2-(G11/$B$4)<0,0,$B$2-(G11/$B$4)) -> 2522 | I11: =$B$3+($B$5*G11) + ($B$6*G11^2) -> 507.06484
A12: Optimall operation | G12: =G11+535 -> 5315 | H12: =IF($B$2-(G12/$B$4)<0,0,$B$2-(G12/$B$4)) -> 2468.5 | I12: =$B$3+($B$5*G12) + ($B$6*G12^2) -> 508.13992
A13: Q | B13: 4166.6667 | D13: Q Critical | E13: Pwf Critical | G13: =G12+535 -> 5850 | H13: =IF($B$2-(G13/$B$4)<0,0,$B$2-(G13/$B$4)) -> 2415 | I13: =$B$3+($B$5*G13) + ($B$6*G13^2) -> 509.27225
A14: P_ipr | B14: =B8-B13/B10 -> 2583.3333 | D14: 3125 | E14: 7.5 | G14: =G13+535 -> 6385 | H14: =IF($B$2-(G14/$B$4)<0,0,$B$2-(G14/$B$4)) -> 2361.5 | I14: =$B$3+($B$5*G14) + ($B$6*G14^2) -> 510.46182
A15: P_VLP | B15: =B3+0.5*B13 -> 2583.3333 | D15: 3125 | E15: 3000 | G15: =G14+535 -> 6920 | H15: =IF($B$2-(G15/$B$4)<0,0,$B$2-(G15/$B$4)) -> 2308 | I15: =$B$3+($B$5*G15) + ($B$6*G15^2) -> 511.70864
A16: Difference | B16: =B14-B15 -> 0 | G16: =G15+535 -> 7455 | H16: =IF($B$2-(G16/$B$4)<0,0,$B$2-(G16/$B$4)) -> 2254.5 | I16: =$B$3+($B$5*G16) + ($B$6*G16^2) -> 513.0127
G17: =G16+535 -> 7990 | H17: =IF($B$2-(G17/$B$4)<0,0,$B$2-(G17/$B$4)) -> 2201 | I17: =$B$3+($B$5*G17) + ($B$6*G17^2) -> 514.37401
A18: With Liquid Loading | G18: =G17+535 -> 8525 | H18: =IF($B$2-(G18/$B$4)<0,0,$B$2-(G18/$B$4)) -> 2147.5 | I18: =$B$3+($B$5*G18) + ($B$6*G18^2) -> 515.79256
A19: Q | B19: 3125 | G19: =G18+535 -> 9060 | H19: =IF($B$2-(G19/$B$4)<0,0,$B$2-(G19/$B$4)) -> 2094 | I19: =$B$3+($B$5*G19) + ($B$6*G19^2) -> 517.26836
A20: P_ipr | B20: =B8-B19/B10 -> 2687.5 | G20: =G19+535 -> 9595 | H20: =IF($B$2-(G20/$B$4)<0,0,$B$2-(G20/$B$4)) -> 2040.5 | I20: =$B$3+($B$5*G20) + ($B$6*G20^2) -> 518.8014
A21: P_vlp | B21: =B9+0.7*B19 -> 2687.5 | G21: =G20+535 -> 10130 | H21: =IF($B$2-(G21/$B$4)<0,0,$B$2-(G21/$B$4)) -> 1987 | I21: =$B$3+($B$5*G21) + ($B$6*G21^2) -> 520.39169
A22: Difference | B22: =B20-B21 -> 0 | G22: =G21+535 -> 10665 | H22: =IF($B$2-(G22/$B$4)<0,0,$B$2-(G22/$B$4)) -> 1933.5 | I22: =$B$3+($B$5*G22) + ($B$6*G22^2) -> 522.03922
G23: =G22+535 -> 11200 | H23: =IF($B$2-(G23/$B$4)<0,0,$B$2-(G23/$B$4)) -> 1880 | I23: =$B$3+($B$5*G23) + ($B$6*G23^2) -> 523.744
A24: Optimal flowrate: 4166.67 | G24: =G23+535 -> 11735 | H24: =IF($B$2-(G24/$B$4)<0,0,$B$2-(G24/$B$4)) -> 1826.5 | I24: =$B$3+($B$5*G24) + ($B$6*G24^2) -> 525.50602
A25: Flow rate with Liquid Loading: 3125.00 | G25: =G24+535 -> 12270 | H25: =IF($B$2-(G25/$B$4)<0,0,$B$2-(G25/$B$4)) -> 1773 | I25: =$B$3+($B$5*G25) + ($B$6*G25^2) -> 527.32529
G26: =G25+535 -> 12805 | H26: =IF($B$2-(G26/$B$4)<0,0,$B$2-(G26/$B$4)) -> 1719.5 | I26: =$B$3+($B$5*G26) + ($B$6*G26^2) -> 529.2018
A27: % of Production Reduction | G27: =G26+535 -> 13340 | H27: =IF($B$2-(G27/$B$4)<0,0,$B$2-(G27/$B$4)) -> 1666 | I27: =$B$3+($B$5*G27) + ($B$6*G27^2) -> 531.13556
A28: % Reduction = (1-(Flow rate with liquid loading/Optimal Flow rate))*100 | G28: =G27+535 -> 13875 | H28: =IF($B$2-(G28/$B$4)<0,0,$B$2-(G28/$B$4)) -> 1612.5 | I28: =$B$3+($B$5*G28) + ($B$6*G28^2) -> 533.12656
A29: =(1-(B19/B13))*100 -> 25 | G29: =G28+535 -> 14410 | H29: =IF($B$2-(G29/$B$4)<0,0,$B$2-(G29/$B$4)) -> 1559 | I29: =$B$3+($B$5*G29) + ($B$6*G29^2) -> 535.17481
A30: % reduction = 25 | G30: =G29+535 -> 14945 | H30: =IF($B$2-(G30/$B$4)<0,0,$B$2-(G30/$B$4)) -> 1505.5 | I30: =$B$3+($B$5*G30) + ($B$6*G30^2) -> 537.2803
G31: =G30+535 -> 15480 | H31: =IF($B$2-(G31/$B$4)<0,0,$B$2-(G31/$B$4)) -> 1452 | I31: =$B$3+($B$5*G31) + ($B$6*G31^2) -> 539.44304
G32: =G31+535 -> 16015 | H32: =IF($B$2-(G32/$B$4)<0,0,$B$2-(G32/$B$4)) -> 1398.5 | I32: =$B$3+($B$5*G32) + ($B$6*G32^2) -> 541.66302
G33: =G32+535 -> 16550 | H33: =IF($B$2-(G33/$B$4)<0,0,$B$2-(G33/$B$4)) -> 1345 | I33: =$B$3+($B$5*G33) + ($B$6*G33^2) -> 543.94025
G34: =G33+535 -> 17085 | H34: =IF($B$2-(G34/$B$4)<0,0,$B$2-(G34/$B$4)) -> 1291.5 | I34: =$B$3+($B$5*G34) + ($B$6*G34^2) -> 546.27472
G35: =G34+535 -> 17620 | H35: =IF($B$2-(G35/$B$4)<0,0,$B$2-(G35/$B$4)) -> 1238 | I35: =$B$3+($B$5*G35) + ($B$6*G35^2) -> 548.66644
G36: =G35+535 -> 18155 | H36: =IF($B$2-(G36/$B$4)<0,0,$B$2-(G36/$B$4)) -> 1184.5 | I36: =$B$3+($B$5*G36) + ($B$6*G36^2) -> 551.1154
G37: =G36+535 -> 18690 | H37: =IF($B$2-(G37/$B$4)<0,0,$B$2-(G37/$B$4)) -> 1131 | I37: =$B$3+($B$5*G37) + ($B$6*G37^2) -> 553.62161
G38: =G37+535 -> 19225 | H38: =IF($B$2-(G38/$B$4)<0,0,$B$2-(G38/$B$4)) -> 1077.5 | I38: =$B$3+($B$5*G38) + ($B$6*G38^2) -> 556.18506
G39: =G38+535 -> 19760 | H39: =IF($B$2-(G39/$B$4)<0,0,$B$2-(G39/$B$4)) -> 1024 | I39: =$B$3+($B$5*G39) + ($B$6*G39^2) -> 558.80576
G40: =G39+535 -> 20295 | H40: =IF($B$2-(G40/$B$4)<0,0,$B$2-(G40/$B$4)) -> 970.5 | I40: =$B$3+($B$5*G40) + ($B$6*G40^2) -> 561.4837
...

Sheet Scenario_Analysis
A1: Case | B1: Gas Price($/MCF) | C1: Monthly OPEX($) | D1: Monthly Discount Rate (Decimal) | E1: NPV($)
A2: Best | B2: 4.5 | C2: 2400 | D2: 0.008 | E2: -1335180.2
A3: Base | B3: 3 | C3: 3000 | D3: 0.0083 | E3: -5345626.1
A4: Worst | B4: 2 | C4: 3600 | D4: 0.012 | E4: -9729472
